<?xml version="1.0" ?>
<robot name="robot_differential_drive" xmlns:xacro="http://www.ros.org/wiki/xacro">

<xacro:include filename="$(find robot_differential_drive_description)/urdf/materials.xacro" />
<xacro:include filename="$(find robot_differential_drive_description)/urdf/robot_differential_drive.trans" />
<xacro:include filename="$(find robot_differential_drive_description)/urdf/robot_differential_drive.gazebo" />
<link name="base_link">
  <inertial>
    <origin xyz="0.10824214180051812 -0.04567748155625664 0.05577696731773351" rpy="0 0 0"/>
    <mass value="3.59892116004878"/>
    <inertia ixx="0.012562" iyy="0.026717" izz="0.035941" ixy="-0.0" iyz="0.0" ixz="0.000918"/>
  </inertial>
  <visual>
    <origin xyz="0 0 0" rpy="0 0 0"/>
    <geometry>
      <mesh filename="package://robot_differential_drive_description/meshes/base_link.stl" scale="0.001 0.001 0.001"/>
    </geometry>
    <material name="silver"/>
  </visual>
  <collision>
    <origin xyz="0 0 0" rpy="0 0 0"/>
    <geometry>
      <mesh filename="package://robot_differential_drive_description/meshes/base_link.stl" scale="0.001 0.001 0.001"/>
    </geometry>
  </collision>
</link>

<link name="right_wheel_1">
  <inertial>
    <origin xyz="3.744771074360581e-07 -0.012500481556256632 0.0" rpy="0 0 0"/>
    <mass value="0.17799934197303036"/>
    <inertia ixx="0.000123" iyy="0.000227" izz="0.000123" ixy="0.0" iyz="-0.0" ixz="0.0"/>
  </inertial>
  <visual>
    <origin xyz="-0.014129 0.155677 -0.05" rpy="0 0 0"/>
    <geometry>
      <mesh filename="package://robot_differential_drive_description/meshes/right_wheel_1.stl" scale="0.001 0.001 0.001"/>
    </geometry>
    <material name="silver"/>
  </visual>
  <collision>
    <origin xyz="-0.014129 0.155677 -0.05" rpy="0 0 0"/>
    <geometry>
      <mesh filename="package://robot_differential_drive_description/meshes/right_wheel_1.stl" scale="0.001 0.001 0.001"/>
    </geometry>
  </collision>
</link>

<link name="left_wheel_1">
  <inertial>
    <origin xyz="3.744771436137162e-07 0.012499518443743349 6.938893903907228e-18" rpy="0 0 0"/>
    <mass value="0.1779993419730304"/>
    <inertia ixx="0.000123" iyy="0.000227" izz="0.000123" ixy="0.0" iyz="0.0" ixz="0.0"/>
  </inertial>
  <visual>
    <origin xyz="-0.014129 -0.064323 -0.05" rpy="0 0 0"/>
    <geometry>
      <mesh filename="package://robot_differential_drive_description/meshes/left_wheel_1.stl" scale="0.001 0.001 0.001"/>
    </geometry>
    <material name="silver"/>
  </visual>
  <collision>
    <origin xyz="-0.014129 -0.064323 -0.05" rpy="0 0 0"/>
    <geometry>
      <mesh filename="package://robot_differential_drive_description/meshes/left_wheel_1.stl" scale="0.001 0.001 0.001"/>
    </geometry>
  </collision>
</link>

<link name="caster_1">
  <inertial>
    <origin xyz="-0.049999625522874486 -4.815562566484743e-07 -0.009375000000000001" rpy="0 0 0"/>
    <mass value="0.2568906492779154"/>
    <inertia ixx="4.2e-05" iyy="4.2e-05" izz="6.4e-05" ixy="0.0" iyz="0.0" ixz="0.0"/>
  </inertial>
  <visual>
    <origin xyz="-0.264129 0.045677 -0.025" rpy="0 0 0"/>
    <geometry>
      <mesh filename="package://robot_differential_drive_description/meshes/caster_1.stl" scale="0.001 0.001 0.001"/>
    </geometry>
    <material name="silver"/>
  </visual>
  <collision>
    <origin xyz="-0.264129 0.045677 -0.025" rpy="0 0 0"/>
    <geometry>
      <mesh filename="package://robot_differential_drive_description/meshes/caster_1.stl" scale="0.001 0.001 0.001"/>
    </geometry>
  </collision>
</link>

<link name="lidar_1">
  <inertial>
    <origin xyz="3.744771255170809e-07 -4.815562566554132e-07 0.01271329027872195" rpy="0 0 0"/>
    <mass value="1.5115445803512537"/>
    <inertia ixx="0.001005" iyy="0.001005" izz="0.001857" ixy="0.0" iyz="0.0" ixz="-0.0"/>
  </inertial>
  <visual>
    <origin xyz="-0.064129 0.045677 -0.125" rpy="0 0 0"/>
    <geometry>
      <mesh filename="package://robot_differential_drive_description/meshes/lidar_1.stl" scale="0.001 0.001 0.001"/>
    </geometry>
    <material name="silver"/>
  </visual>
  <collision>
    <origin xyz="-0.064129 0.045677 -0.125" rpy="0 0 0"/>
    <geometry>
      <mesh filename="package://robot_differential_drive_description/meshes/lidar_1.stl" scale="0.001 0.001 0.001"/>
    </geometry>
  </collision>
</link>

<link name="camera_1">
  <inertial>
    <origin xyz="0.007500374477125482 0.009999518443743333 -6.938893903907228e-18" rpy="0 0 0"/>
    <mass value="0.011883648677994093"/>
    <inertia ixx="2e-06" iyy="1e-06" izz="2e-06" ixy="0.0" iyz="-0.0" ixz="-0.0"/>
  </inertial>
  <visual>
    <origin xyz="-0.264129 0.045677 -0.049" rpy="0 0 0"/>
    <geometry>
      <mesh filename="package://robot_differential_drive_description/meshes/camera_1.stl" scale="0.001 0.001 0.001"/>
    </geometry>
    <material name="silver"/>
  </visual>
  <collision>
    <origin xyz="-0.264129 0.045677 -0.049" rpy="0 0 0"/>
    <geometry>
      <mesh filename="package://robot_differential_drive_description/meshes/camera_1.stl" scale="0.001 0.001 0.001"/>
    </geometry>
  </collision>
</link>

<joint name="Revolute 1" type="continuous">
  <origin xyz="0.014129 -0.155677 0.05" rpy="0 0 0"/>
  <parent link="base_link"/>
  <child link="right_wheel_1"/>
  <axis xyz="0.0 1.0 0.0"/>
</joint>

<joint name="Revolute 2" type="continuous">
  <origin xyz="0.014129 0.064323 0.05" rpy="0 0 0"/>
  <parent link="base_link"/>
  <child link="left_wheel_1"/>
  <axis xyz="0.0 1.0 0.0"/>
</joint>

<joint name="Rigid 3" type="fixed">
  <origin xyz="0.264129 -0.045677 0.025" rpy="0 0 0"/>
  <parent link="base_link"/>
  <child link="caster_1"/>
</joint>

<joint name="Rigid 4" type="fixed">
  <origin xyz="0.064129 -0.045677 0.125" rpy="0 0 0"/>
  <parent link="base_link"/>
  <child link="lidar_1"/>
</joint>

<joint name="Rigid 5" type="fixed">
  <origin xyz="0.264129 -0.045677 0.049" rpy="0 0 0"/>
  <parent link="base_link"/>
  <child link="camera_1"/>
</joint>

</robot>
